<?xml version="1.0" ?>
<robot name="indy" version="1.0">
  <material name="black">
    <color rgba="0.0 0.0 0.0 0.5"/>
  </material>
  <material name="blue">
    <color rgba="0.0 0.0 0.8 0.5"/>
  </material>
  <material name="green">
    <color rgba="0.0 0.8 0.0 0.5"/>
  </material>
  <material name="grey_">
    <color rgba="0.2 0.2 0.2 0.5"/>
  </material>
  <material name="orange">
    <color rgba="1.0 0.423529411765 0.0392156862745 0.5"/>
  </material>
  <material name="brown">
    <color rgba="0.870588235294 0.811764705882 0.764705882353 0.5"/>
  </material>
  <material name="red">
    <color rgba="0.8 0.0 0.0 0.5"/>
  </material>
  <material name="white">
    <color rgba="1.0 1.0 1.0 0.5"/>
  </material>
  <material name="metal">
    <color rgba="0.76862745098 0.749019607843 0.729411764706 0.5"/>
  </material>
  <material name="metal_grey">
    <color rgba="0.501960784314 0.501960784314 0.501960784314 0.5"/>
  </material>
  <material name="metal_white">
    <color rgba="0.866666666667 0.866666666667 0.890196078431 0.5"/>
  </material>
  <link name="indy0_link0">
    <inertial>
      <origin rpy="0.0 0.0 0.0" xyz="0.0 0.0 0.0"/>
      <mass value="0.0"/>
      <inertia ixx="0.00572623" ixy="2.51e-06" ixz="-0.0001138" iyy="0.00558959" iyz="-1.4e-07" izz="0.00966674"/>
    </inertial>
    <visual>
      <origin rpy="0.0 0.0 0.0" xyz="0.0 0.0 0.0"/>
      <geometry>
        <mesh filename="meshes/stl/Indy7_0.stl"/>
      </geometry>
      <material name="metal_white"/>
    </visual>
  </link>
  <link name="indy0_link1">
    <inertial>
      <origin rpy="0.0 0.0 0.0" xyz="0.0 0.0 0.0"/>
      <mass value="11.8030102"/>
      <inertia ixx="0.15418559" ixy="-2.35e-06" ixz="1.739e-05" iyy="0.12937017" iyz="-0.04854267" izz="0.05964415"/>
    </inertial>
    <visual>
      <origin rpy="0.0 0.0 0.0" xyz="0.0 0.0 0.0"/>
      <geometry>
        <mesh filename="meshes/stl/Indy7_1.stl"/>
      </geometry>
      <material name="metal_white"/>
    </visual>
  </link>
  <link name="indy0_link2">
    <inertial>
      <origin rpy="0.0 0.0 0.0" xyz="0.0 0.0 0.0"/>
      <mass value="7.99292141"/>
      <inertia ixx="0.2935698" ixy="-4e-07" ixz="1.441e-05" iyy="0.28094142" iyz="0.03727972" izz="0.03620609"/>
    </inertial>
    <visual>
      <origin rpy="0.0 0.0 0.0" xyz="0.0 0.0 0.0"/>
      <geometry>
        <mesh filename="meshes/stl/Indy7_2.stl"/>
      </geometry>
      <material name="metal_white"/>
    </visual>
  </link>
  <link name="indy0_link3">
    <inertial>
      <origin rpy="0.0 0.0 0.0" xyz="0.0 0.0 0.0"/>
      <mass value="2.99134127"/>
      <inertia ixx="0.03424593" ixy="1.49e-06" ixz="7.24e-06" iyy="0.03406024" iyz="0.00186009" izz="0.00450477"/>
    </inertial>
    <visual>
      <origin rpy="0.0 0.0 0.0" xyz="0.0 0.0 0.0"/>
      <geometry>
        <mesh filename="meshes/stl/Indy7_3.stl"/>
      </geometry>
      <material name="metal_white"/>
    </visual>
  </link>
  <link name="indy0_link4">
    <inertial>
      <origin rpy="0.0 0.0 0.0" xyz="0.0 0.0 0.0"/>
      <mass value="2.12317035"/>
      <inertia ixx="0.00670405" ixy="3.75e-06" ixz="1.5e-06" iyy="0.00279246" iyz="-0.00127967" izz="0.00619341"/>
    </inertial>
    <visual>
      <origin rpy="0.0 0.0 0.0" xyz="0.0 0.0 0.0"/>
      <geometry>
        <mesh filename="meshes/stl/Indy7_4.stl"/>
      </geometry>
      <material name="metal_white"/>
    </visual>
  </link>
  <link name="indy0_link5">
    <inertial>
      <origin rpy="0.0 0.0 0.0" xyz="0.0 0.0 0.0"/>
      <mass value="2.28865091"/>
      <inertia ixx="0.00994891" ixy="1.4e-07" ixz="3.21e-06" iyy="0.00978189" iyz="-0.00093546" izz="0.00271492"/>
    </inertial>
    <visual>
      <origin rpy="0.0 0.0 0.0" xyz="0.0 0.0 0.0"/>
      <geometry>
        <mesh filename="meshes/stl/Indy7_5.stl"/>
      </geometry>
      <material name="metal_white"/>
    </visual>
  </link>
  <link name="indy0_link6">
    <inertial>
      <origin rpy="0.0 0.0 0.0" xyz="0.0 0.0 0.0"/>
      <mass value="0.40083918"/>
      <inertia ixx="0.00043534" ixy="1.3e-07" ixz="-2e-08" iyy="0.00044549" iyz="5.1e-07" izz="0.00059634"/>
    </inertial>
    <visual>
      <origin rpy="0.0 0.0 0.0" xyz="0.0 0.0 0.0"/>
      <geometry>
        <mesh filename="meshes/stl/Indy7_6.stl"/>
      </geometry>
      <material name="metal_white"/>
    </visual>
  </link>
  <joint name="indy0_joint0" type="revolute">
    <origin rpy="0.0 0.0 0.0" xyz="0.0 0.0 0.0775"/>
    <axis xyz="0.0 0.0 1.0"/>
    <parent link="indy0_link0"/>
    <child link="indy0_link1"/>
    <limit effort="0.7853981633974483" lower="-3.05432619099" upper="3.05432619099" velocity="0.6544984694978736"/>
  </joint>
  <joint name="indy0_joint1" type="revolute">
    <origin rpy="1.57079632679 1.57079632679 0.0" xyz="0.0 -0.109 0.222"/>
    <axis xyz="0.0 0.0 1.0"/>
    <parent link="indy0_link1"/>
    <child link="indy0_link2"/>
    <limit effort="0.7853981633974483" lower="-3.05432619099" upper="3.05432619099" velocity="0.6544984694978736"/>
  </joint>
  <joint name="indy0_joint2" type="revolute">
    <origin rpy="0.0 0.0 0.0" xyz="-0.45 0.0 -0.0305"/>
    <axis xyz="0.0 0.0 1.0"/>
    <parent link="indy0_link2"/>
    <child link="indy0_link3"/>
    <limit effort="0.7853981633974483" lower="-3.05432619099" upper="3.05432619099" velocity="0.6544984694978736"/>
  </joint>
  <joint name="indy0_joint3" type="revolute">
    <origin rpy="-1.57079632679 0.0 1.57079632679" xyz="-0.267 0.0 -0.075"/>
    <axis xyz="0.0 0.0 1.0"/>
    <parent link="indy0_link3"/>
    <child link="indy0_link4"/>
    <limit effort="0.7853981633974483" lower="-3.05432619099" upper="3.05432619099" velocity="0.7853981633974483"/>
  </joint>
  <joint name="indy0_joint4" type="revolute">
    <origin rpy="1.57079632679 1.57079632679 0.0" xyz="0.0 -0.114 0.083"/>
    <axis xyz="0.0 0.0 1.0"/>
    <parent link="indy0_link4"/>
    <child link="indy0_link5"/>
    <limit effort="0.7853981633974483" lower="-3.05432619099" upper="3.05432619099" velocity="0.7853981633974483"/>
  </joint>
  <joint name="indy0_joint5" type="revolute">
    <origin rpy="-1.57079632679 0.0 1.57079632679" xyz="-0.168 0.0 0.069"/>
    <axis xyz="0.0 0.0 1.0"/>
    <parent link="indy0_link5"/>
    <child link="indy0_link6"/>
    <limit effort="0.7853981633974483" lower="-3.75245789179" upper="3.75245789179" velocity="0.7853981633974483"/>
  </joint>
</robot>